Workbook
Name \0: #REF!
Name \a: #REF!
Name \e: #REF!
Name \F: #REF!
Name \I: #REF!
Name \P: #REF!
Name \q: #REF!
Name \x: #REF!
Name \z: #REF!
Name __RE1: #REF!
Name _1001: #REF!
Name _1Excel_BuiltIn__FilterDatabase_1: #REF!
Name _28655: #REF!
Name _28698: #REF!
Name _28699: #REF!
Name _28724: #REF!
Name _28727: #REF!
Name _28734: #REF!
Name _28738: #REF!
Name _28745: #REF!
Name _28748: #REF!
Name _30662_2011TTL: #REF!
Name _30687: #REF!
Name _30688: #REF!
Name _30689: #REF!
Name _30690: #REF!
Name _31143: #REF!
Name _31771: #REF!
Name _32781: #REF!
Name _AU19452: #REF!
Name _AU24412: #REF!
Name _AU25231: #REF!
Name _AU25799: #REF!
Name _AU26137: #REF!
Name _AU26725: #REF!
Name _AU27858: #REF!
Name _AU28837: #REF!
Name _AU29288: #REF!
Name _AU295224: #REF!
Name _AU295249: #REF!
Name _AU298980: #REF!
Name _AU299820: #REF!
Name _AU299933: #REF!
Name _AU300040: #REF!
Name _AU300384: #REF!
Name _au300879: #REF!
Name _AU301555: #REF!
Name _AU301558: #REF!
Name _AU301565: #REF!
Name _AU302053: #REF!
Name _AU302054: #REF!
Name _AU302055: #REF!
Name _AU302281: #REF!
Name _AU303526: #REF!
Name _AU303617: #REF!
Name _AU305018: #REF!
Name _AU305578: #REF!
Name _AU32838: #REF!
Name _AU33316: #REF!
Name _AU33877: #REF!

Sheet Template
M1: V6
A2: Stibo Attribute | B2: Stibo Attribute ID | C2: Stibo Validation | D2: Cluster | E2: Grouping | F2: Attributes Description | G2: Field Mapping Type | H2: Brand File Name & Link | I2: Brand File Sheet Name | J2: Field Name in the Brand File | K2: Mapping Logic | L2: Mapping file for additional Brand specific mapping | M2: mapping logic | N2: Inline/Licensed | O2: Footwear | P2: Apparel | Q2: Accessories | R2: Sport Equipment
A3: Country | B3: =VLOOKUP(A3,MDD!A:B,2,0) -> AT_Country | C3: =VLOOKUP(A3,MDD!A:C,3,0) -> LOV | D3: Basic | F3: Co Dependent with Description E.g : ID - Indonesia PH - Philiphine TH - Thailand SG - Singapore MY - Malaysia VN - Vietnam KH : Cambodia
A4: Company | B4: =VLOOKUP(A4,MDD!A:B,2,0) -> AT_CompanyCode | C4: =VLOOKUP(A4,MDD!A:C,3,0) -> LOV | D4: Basic | F4: Co Dependent with Description 0888 - PT. Map Aktif Adiperkasa 0886 - PT. MAP FTL Adiperkasa 0882 - Magna Management Asia etc (Refer to LOV)
A5: SBU | B5: =VLOOKUP(A5,MDD!A:B,2,0) -> AT_SBU | C5: =VLOOKUP(A5,MDD!A:C,3,0) -> LOV | D5: Basic | F5: Co Dependent with Description E.g SP - Sports FQ - Footlocker Etc (refer to LOV)
A6: Brand | B6: =VLOOKUP(A6,MDD!A:B,2,0) -> AT_Brand | C6: =VLOOKUP(A6,MDD!A:C,3,0) -> LOV | D6: Basic | F6: Co Dependent with Description E.g ADI - Adidas NIK - Nike NEW - New Balance Etc (refer to LOV)
A7: Brand Group | B7: =VLOOKUP(A7,MDD!A:B,2,0) -> AT_BrandGroup | C7: =VLOOKUP(A7,MDD!A:C,3,0) -> LOV | D7: Basic | F7: Multiple brand codes that managed under 1 brand group e.g. Adidas, Lego, Hasbro
A8: Brand Type | B8: =VLOOKUP(A8,MDD!A:B,2,0) -> AT_BrandType | C8: =VLOOKUP(A8,MDD!A:C,3,0) -> LOV | D8: Commercial | F8: Whether a brand act as a retailer, selling directly to customers (MAA brands, SDI brands) or as a distributor (Non-MAA brands, Non-SDI brands)
A9: Brand Category | B9: =VLOOKUP(A9,MDD!A:B,2,0) -> AT_BrandCategory | C9: =VLOOKUP(A9,MDD!A:C,3,0) -> LOV | D9: Commercial | F9: Group of brands that classified based on their performance/ contribution e.g. Top brands, Selected brands, Non-Top brands
A10: Brand Status | B10: =VLOOKUP(A10,MDD!A:B,2,0) -> AT_BrandStatus | C10: =VLOOKUP(A10,MDD!A:C,3,0) -> LOV | D10: Commercial | F10: Indicating whether the brands is actively being sold or, no longer continued or exit the market (Active/Discontinue)
A11: BY Indicator | B11: =VLOOKUP(A11,MDD!A:B,2,0) -> AT_BYIndicator | C11: =VLOOKUP(A11,MDD!A:C,3,0) -> LOV | D11: System indicator | F11: Article to be ordered
A12: SAP Indicator | B12: =VLOOKUP(A12,MDD!A:B,2,0) -> AT_SAPIndicator | C12: =VLOOKUP(A12,MDD!A:C,3,0) -> LOV | D12: System indicator | F12: Article has been created
A13: Ecom Indicator | B13: =VLOOKUP(A13,MDD!A:B,2,0) -> AT_EcomIndicator | C13: =VLOOKUP(A13,MDD!A:C,3,0) -> LOV | D13: System indicator | F13: Article to be Publish at Online Sales Channel
A14: Principal Style Code | B14: =VLOOKUP(A14,MDD!A:B,2,0) -> AT_PrincipalStyleCode | C14: =VLOOKUP(A14,MDD!A:C,3,0) -> text | D14: Basic | F14: Original Principal Code
A15: Principal Style Description | B15: =VLOOKUP(A15,MDD!A:B,2,0) -> AT_PrincipalStyleDescription | C15: =VLOOKUP(A15,MDD!A:C,3,0) -> text | D15: Basic | E15: Description | F15: Original Principal Product Name
A16: Principal Color Code | B16: =VLOOKUP(A16,MDD!A:B,2,0) -> AT_PrincipalColorCode | C16: =VLOOKUP(A16,MDD!A:C,3,0) -> text | D16: Basic | E16: Color | F16: Original Principal Color
A17: Principal Color Description | B17: =VLOOKUP(A17,MDD!A:B,2,0) -> AT_PrincipalColorName | C17: =VLOOKUP(A17,MDD!A:C,3,0) -> text | D17: Basic | E17: Color | F17: Original Principal Color Description
A18: Principal Gender Code | B18: =VLOOKUP(A18,MDD!A:B,2,0) -> AT_PrincipalGenderCode | C18: =VLOOKUP(A18,MDD!A:C,3,0) -> text | D18: Basic | E18: Gender | F18: Original Principal Gender
A19: Principal Gender Description | B19: =VLOOKUP(A19,MDD!A:B,2,0) -> AT_PrincipalGenderDescription | C19: =VLOOKUP(A19,MDD!A:C,3,0) -> text | D19: Basic | E19: Gender | F19: Original Principal Gender Description
A20: Principal Age Code | B20: =VLOOKUP(A20,MDD!A:B,2,0) -> AT_PrincipalAgeCode | C20: =VLOOKUP(A20,MDD!A:C,3,0) -> text | D20: Basic | E20: Age | F20: Original Principal Age
A21: Principal Age Description | B21: =VLOOKUP(A21,MDD!A:B,2,0) -> AT_PrincipalAgeDescription | C21: =VLOOKUP(A21,MDD!A:C,3,0) -> text | D21: Basic | E21: Age | F21: Original Principal Age Description
A22: Principal Size | B22: =VLOOKUP(A22,MDD!A:B,2,0) -> AT_PrincipalSize | C22: =VLOOKUP(A22,MDD!A:C,3,0) -> text | D22: Basic | E22: Sizing | F22: Original Size from Principal (co-dependent with description)
A23: SAP Style Code | B23: =VLOOKUP(A23,MDD!A:B,2,0) -> AT_SAPStyleCode | C23: =VLOOKUP(A23,MDD!A:C,3,0) -> text | D23: Basic | F23: Adjusted principal style code that has been map to SAP generic (without brand code)
A24: Generic | B24: =VLOOKUP(A24,MDD!A:B,2,0) -> AT_Generic | C24: =VLOOKUP(A24,MDD!A:C,3,0) -> text | D24: Basic | F24: MAA Generic Code (Max 12 Digits - 3 Digits brand code + 9 Digits Principal Style)
A25: Generic Description | B25: =VLOOKUP(A25,MDD!A:B,2,0) -> AT_GenericDescription | C25: =VLOOKUP(A25,MDD!A:C,3,0) -> regexp | D25: Basic | E25: Description | F25: MAA Generic Description Mapping (Max 40 Digits - 3 Digits brand code + Principal style + (Age/Gender) + Color
A26: Variant | B26: =VLOOKUP(A26,MDD!A:B,2,0) -> AT_Variant | C26: =VLOOKUP(A26,MDD!A:C,3,0) -> text | D26: Basic | F26: MAA Article Code (Max 18 Digits - Generic code + 3 Digits MAA / SAP Color (103 color guidance) + 3 Digits MAA size code mapping
A27: Variant Description | B27: =VLOOKUP(A27,MDD!A:B,2,0) -> AT_VariantDescription | C27: =VLOOKUP(A27,MDD!A:C,3,0) -> text | D27: Basic | E27: Description | F27: MAA Generic Description Mapping (Max 40 Digits - 3 Digits brand code + Principal style + (Age/Gender) + Color + Size
A28: SAP Color | B28: =VLOOKUP(A28,MDD!A:B,2,0) -> AT_Color | C28: =VLOOKUP(A28,MDD!A:C,3,0) -> LOV | D28: Basic | E28: Color | F28: MAA 103 Basic SAP Color Code & Description
A29: SAP Size | B29: =VLOOKUP(A29,MDD!A:B,2,0) -> AT_Size | C29: =VLOOKUP(A29,MDD!A:C,3,0) -> LOV | D29: Basic | E29: Sizing | F29: MAA SAP Size Code & Description
A30: Created on | B30: =VLOOKUP(A30,MDD!A:B,2,0) -> AT_Createdon | C30: =VLOOKUP(A30,MDD!A:C,3,0) -> legacyisodatetime | D30: Basic | F30: When is the creation date
A31: Created by | B31: =VLOOKUP(A31,MDD!A:B,2,0) -> AT_Createdby | C31: =VLOOKUP(A31,MDD!A:C,3,0) -> text | D31: Basic | F31: Who is creating the articles
A32: Musical Box Article Code | B32: =VLOOKUP(A32,MDD!A:B,2,0) -> AT_MusicalBoxArticleCode | C32: =VLOOKUP(A32,MDD!A:C,3,0) -> text | D32: Basic | F32: MAA Musical Box Code (Max 18 Digits - 3 Digits brand code + 3 digits of MB- +9 digits of SAP Style Code + 3 Digits Assortment Code)
A33: MB Style code | B33: =VLOOKUP(A33,MDD!A:B,2,0) -> AT_MBStyleCode | C33: =VLOOKUP(A33,MDD!A:C,3,0) -> text | D33: Basic | F33: Max 12 digits MB Style (MB- + SAP Style Code )
A34: MB Assortment Code | B34: =VLOOKUP(A34,MDD!A:B,2,0) -> AT_MBAssortmentCode | C34: =VLOOKUP(A34,MDD!A:C,3,0) -> LOV | D34: Basic | F34: 3 Digits Assortment code (based on matrix of qty per sizes)
A35: Musical Box Article Description | B35: =VLOOKUP(A35,MDD!A:B,2,0) -> AT_MusicalBoxArticleDescription | C35: =VLOOKUP(A35,MDD!A:C,3,0) -> text | D35: Basic | E35: Description | F35: MAA Musical Box Description Mapping (Max 40 Digits - 3 Digits brand code + Principal style + (Age/Gender) + Color + (-MB)
A36: Musical Box Components Qty | B36: =VLOOKUP(A36,MDD!A:B,2,0) -> AT_MusicalBoxComponentsQty | C36: =VLOOKUP(A36,MDD!A:C,3,0) -> LOV | D36: Basic | F36: Components qty of Musical Box Articles : Breakdown qty per sizes
A37: Musical Box UOM | B37: =VLOOKUP(A37,MDD!A:B,2,0) -> AT_MusicalBoxUOM | C37: =VLOOKUP(A37,MDD!A:C,3,0) -> LOV | D37: Basic | F37: UOM for Musical Box (Default : CAR)
A38: SAP Age | B38: =VLOOKUP(A38,MDD!A:B,2,0) -> AT_SAPAge | C38: =VLOOKUP(A38,MDD!A:C,3,0) -> LOV | D38: Basic | E38: Age | F38: MAA SAP Age (Co - Dependent with Description) E.g : CH - Children AA - All Ages AD - Adults
A39: SAP Gender | B39: =VLOOKUP(A39,MDD!A:B,2,0) -> AT_Gender | C39: =VLOOKUP(A39,MDD!A:C,3,0) -> LOV | D39: Basic | E39: Gender | F39: MAA SAP Gender (co dependent with description) E.g : M - Male F - Female U - Unisex
A40: Season | B40: =VLOOKUP(A40,MDD!A:B,2,0) -> AT_Season | C40: =VLOOKUP(A40,MDD!A:C,3,0) -> LOV | D40: Basic | F40: MAA SAP Season (Co Dependent with Description) E.g : SP - Spring SM - Summer FW - Fall Winter SS - Spring Summer etc (refer to LOV)
...

Sheet Adidas-API
G1: Linelist V6 | J1: API | M1: V6
A2: Stibo Attribute | B2: Stibo Attribute ID | C2: Stibo Validation | D2: Cluster | E2: Grouping | F2: Attributes Description | G2: Field Mapping Type | H2: Brand File Name & Link | I2: Brand File Sheet Name | J2: Field Name in the Brand File | K2: Mapping Logic | L2: Mapping file for additional Brand specific mapping | M2: mapping logic | N2: Inline | O2: Footwear | P2: Apparel | Q2: Accessories | R2: Equipment
A3: Country | B3: =VLOOKUP(A3,MDD!A:B,2,0) -> AT_Country | C3: =VLOOKUP(A3,MDD!A:C,3,0) -> LOV | D3: Basic | F3: Co Dependent with Description E.g : ID - Indonesia PH - Philiphine TH - Thailand SG - Singapore MY - Malaysia VN - Vietnam KH : Cambodia | G3: Manual Input in Portal | J3: TBC | M3: Refer to LOV | O3: D | P3: D | Q3: D | R3: D | V3: API SOURCES - is it only DTB?
A4: Company | B4: =VLOOKUP(A4,MDD!A:B,2,0) -> AT_CompanyCode | C4: =VLOOKUP(A4,MDD!A:C,3,0) -> LOV | D4: Basic | F4: Co Dependent with Description 0888 - PT. Map Aktif Adiperkasa 0886 - PT. MAP FTL Adiperkasa 0882 - Magna Management Asia etc (Refer to LOV) | G4: Manual Input in Portal | J4: #N/A | M4: Refer to LOV | O4: D | P4: D | Q4: D | R4: D | V4: Fields/Columns
A5: SBU | B5: =VLOOKUP(A5,MDD!A:B,2,0) -> AT_SBU | C5: =VLOOKUP(A5,MDD!A:C,3,0) -> LOV | D5: Basic | F5: Co Dependent with Description E.g SP - Sports FQ - Footlocker Etc (refer to LOV) | G5: Manual Input in Portal | J5: #N/A | M5: Refer to LOV | O5: D | P5: D | Q5: D | R5: D
A6: Brand | B6: =VLOOKUP(A6,MDD!A:B,2,0) -> AT_Brand | C6: =VLOOKUP(A6,MDD!A:C,3,0) -> LOV | D6: Basic | F6: Co Dependent with Description E.g ADI - Adidas NIK - Nike NEW - New Balance Etc (refer to LOV) | G6: Manual Input in Portal | J6: #N/A | M6: Refer to LOV | O6: D | P6: D | Q6: D | R6: D | U6: Fiellds/Attributes MAA Needs
A7: Brand Group | B7: =VLOOKUP(A7,MDD!A:B,2,0) -> AT_BrandGroup | C7: =VLOOKUP(A7,MDD!A:C,3,0) -> LOV | D7: Basic | F7: Multiple brand codes that managed under 1 brand group e.g. Adidas, Lego, Hasbro | G7: Formula in System | J7: #N/A | M7: Refer to LOV | O7: F | P7: F | Q7: F | R7: F | U7: Thumbnail image | V7: Criteria 1
A8: Brand Type | B8: =VLOOKUP(A8,MDD!A:B,2,0) -> AT_BrandType | C8: =VLOOKUP(A8,MDD!A:C,3,0) -> LOV | D8: Commercial | F8: Whether a brand act as a retailer, selling directly to customers (MAA brands, SDI brands) or as a distributor (Non-MAA brands, Non-SDI brands) | G8: Formula in System | J8: #N/A | M8: Refer to LOV | O8: F | P8: F | Q8: F | R8: F | V8: View : Standard View
A9: Brand Category | B9: =VLOOKUP(A9,MDD!A:B,2,0) -> AT_BrandCategory | C9: =VLOOKUP(A9,MDD!A:C,3,0) -> LOV | D9: Commercial | F9: Group of brands that classified based on their performance/ contribution e.g. Top brands, Selected brands, Non-Top brands | G9: Formula in System | J9: #N/A | M9: Refer to LOV | O9: F | P9: F | Q9: F | R9: F | V9: Category : On Model
A10: Brand Status | B10: =VLOOKUP(A10,MDD!A:B,2,0) -> AT_BrandStatus | C10: =VLOOKUP(A10,MDD!A:C,3,0) -> LOV | D10: Commercial | F10: Indicating whether the brands is actively being sold or, no longer continued or exit the market (Active/Discontinue) | G10: Formula in System | J10: #N/A | M10: Refer to LOV | O10: F | P10: F | Q10: F | R10: F | V10: Background : White
A11: BY Indicator | B11: =VLOOKUP(A11,MDD!A:B,2,0) -> AT_BYIndicator | C11: =VLOOKUP(A11,MDD!A:C,3,0) -> LOV | D11: System indicator | F11: Article to be ordered | G11: Formula in System | J11: #N/A | O11: F | P11: F | Q11: F | R11: F
A12: SAP Indicator | B12: =VLOOKUP(A12,MDD!A:B,2,0) -> AT_SAPIndicator | C12: =VLOOKUP(A12,MDD!A:C,3,0) -> LOV | D12: System indicator | F12: Article has been created | G12: Formula in System | J12: #N/A | O12: F | P12: F | Q12: F | R12: F | V12: Criteria 2
A13: Ecom Indicator | B13: =VLOOKUP(A13,MDD!A:B,2,0) -> AT_EcomIndicator | C13: =VLOOKUP(A13,MDD!A:C,3,0) -> LOV | D13: System indicator | F13: Article to be Publish at Online Sales Channel | G13: Manual Input | J13: #N/A | O13: D | P13: D | Q13: D | R13: D | V13: View : Side Lateral Center View
A14: Principal Style Code | B14: =VLOOKUP(A14,MDD!A:B,2,0) -> AT_PrincipalStyleCode | C14: =VLOOKUP(A14,MDD!A:C,3,0) -> text | D14: Basic | F14: Original Principal Code | G14: Mapping from principal | J14: Article No. | M14: Footwear/Apparel/Accessories Linelist: column 'Article No.' or 'Article Number' Backlog (other excel 1) : Column 'Material No' Notes: Backlog will be ready before shipment. | O14: A | P14: A | Q14: A | R14: A | V14: Category : Photography
A15: Principal Style Description | B15: =VLOOKUP(A15,MDD!A:B,2,0) -> AT_PrincipalStyleDescription | C15: =VLOOKUP(A15,MDD!A:C,3,0) -> text | D15: Basic | E15: Description | F15: Original Principal Product Name | G15: Mapping from principal | J15: Article Name | M15: Footwear/Apparel/Accessories Linelist: column 'Model Name' Notes: Sometimes model name is not available, so will use Dummy/0 and it will be fixed later on after the data updated | O15: A | P15: A | Q15: A | R15: A | V15: Background : White
A16: Principal Color Code | B16: =VLOOKUP(A16,MDD!A:B,2,0) -> AT_PrincipalColorCode | C16: =VLOOKUP(A16,MDD!A:C,3,0) -> text | D16: Basic | E16: Color | F16: Original Principal Color | G16: Mapping from principal | J16: #N/A | M16: No color code. Notes : for Adidas, there's no multiple color in 1 style code | O16: E | P16: E | Q16: E | R16: E
A17: Principal Color Description | B17: =VLOOKUP(A17,MDD!A:B,2,0) -> AT_PrincipalColorName | C17: =VLOOKUP(A17,MDD!A:C,3,0) -> text | D17: Basic | E17: Color | F17: Original Principal Color Description | G17: Mapping from principal | J17: B2B Color1 | M17: Footwear/Apparel/Accessories DTB (downloaded from portal) Column : 'B2B Color 1' Portal Note: AI image recognition might be able to support this mapping | O17: A | P17: A | Q17: A | R17: A | V17: Criteria 3
A18: Principal Gender Code | B18: =VLOOKUP(A18,MDD!A:B,2,0) -> AT_PrincipalGenderCode | C18: =VLOOKUP(A18,MDD!A:C,3,0) -> text | D18: Basic | E18: Gender | F18: Original Principal Gender | G18: Not Avaiable | J18: #N/A | M18: No gender code. | O18: E | P18: E | Q18: E | R18: E | V18: View : Left Side Center View
A19: Principal Gender Description | B19: =VLOOKUP(A19,MDD!A:B,2,0) -> AT_PrincipalGenderDescription | C19: =VLOOKUP(A19,MDD!A:C,3,0) -> text | D19: Basic | E19: Gender | F19: Original Principal Gender Description | G19: Formula in System | J19: B2B Gender | M19: Footwear/Apparel/Accessories Linelist: column 'Gender' DTB (Downloaded from portal) : Column 'Gender' | O19: A | P19: A | Q19: A | R19: A | V19: Category : Photography
A20: Principal Age Code | B20: =VLOOKUP(A20,MDD!A:B,2,0) -> AT_PrincipalAgeCode | C20: =VLOOKUP(A20,MDD!A:C,3,0) -> text | D20: Basic | E20: Age | F20: Original Principal Age | G20: Not Avaiable | J20: #N/A | M20: No age code. | O20: E | P20: E | Q20: E | R20: E | V20: Background : White
A21: Principal Age Description | B21: =VLOOKUP(A21,MDD!A:B,2,0) -> AT_PrincipalAgeDescription | C21: =VLOOKUP(A21,MDD!A:C,3,0) -> text | D21: Basic | E21: Age | F21: Original Principal Age Description | G21: Formula in System | J21: B2B Age Group | M21: Footwear/Apparel/Accessories Linelist: column 'Age Group' DTB (Downloaded from portal) : Column 'Age Group' | O21: A | P21: A | Q21: A | R21: A
A22: Principal Size | B22: =VLOOKUP(A22,MDD!A:B,2,0) -> AT_PrincipalSize | C22: =VLOOKUP(A22,MDD!A:C,3,0) -> text | D22: Basic | E22: Sizing | F22: Original Size from Principal (co-dependent with description) | G22: Mapping from principal | J22: #N/A | M22: Footwear/Apparel/Accessories Backlog (Other excel) Sheet: EAN List, column 'Size' Notes: There are 2 tab sheets in Backlog file. 1st, backlog for generic, 2nd is sizing and EAN list. | O22: A | P22: A | Q22: A | R22: A | V22: Criteria 4
A23: SAP Style Code | B23: =VLOOKUP(A23,MDD!A:B,2,0) -> AT_SAPStyleCode | C23: =VLOOKUP(A23,MDD!A:C,3,0) -> text | D23: Basic | F23: Adjusted principal style code that has been map to SAP generic (without brand code) | G23: Formula in System | J23: #N/A | M23: Footwear/Apparel/Accessories Principal Style Code (max 9 digits) Example: 123456 | O23: A | P23: A | Q23: A | R23: A | V23: View : Any view available in DTB
A24: Generic | B24: =VLOOKUP(A24,MDD!A:B,2,0) -> AT_Generic | C24: =VLOOKUP(A24,MDD!A:C,3,0) -> text | D24: Basic | F24: MAA Generic Code (Max 12 Digits - 3 Digits brand code + 9 Digits Principal Style) | G24: Formula in System | J24: #N/A | M24: Footwear/Apparel/Accessories Mapping formula: Brand Code + Principal Style Code Example: ADI123456 | O24: F | P24: F | Q24: F | R24: F | V24: Category : Any category in DTB
A25: Generic Description | B25: =VLOOKUP(A25,MDD!A:B,2,0) -> AT_GenericDescription | C25: =VLOOKUP(A25,MDD!A:C,3,0) -> regexp | D25: Basic | E25: Description | F25: MAA Generic Description Mapping (Max 40 Digits - 3 Digits brand code + Principal style + (Age/Gender) + Color | G25: Formula in System | J25: #N/A | M25: Mapping formula : 3 Digits Brand Code + Principal Style Description + SAP (Age/Gender) + SAP Mapping Color Description | O25: F | P25: F | Q25: F | R25: F | V25: Background : Any Background in DTB
A26: Variant | B26: =VLOOKUP(A26,MDD!A:B,2,0) -> AT_Variant | C26: =VLOOKUP(A26,MDD!A:C,3,0) -> text | D26: Basic | F26: MAA Article Code (Max 18 Digits - Generic code + 3 Digits MAA / SAP Color (103 color guidance) + 3 Digits MAA size code mapping | G26: Formula in System | J26: #N/A | M26: Footwear/Apparel/Accessories Mapping formula: Generic + 3 Digits SAP Color Code + 3 Digits SAP Size code Example: ADI123456005006 | O26: F | P26: F | Q26: F | R26: F | U26: Principal style code | V26: Article No.
A27: Variant Description | B27: =VLOOKUP(A27,MDD!A:B,2,0) -> AT_VariantDescription | C27: =VLOOKUP(A27,MDD!A:C,3,0) -> text | D27: Basic | E27: Description | F27: MAA Generic Description Mapping (Max 40 Digits - 3 Digits brand code + Principal style + (Age/Gender) + Color + Size | G27: Formula in System | J27: #N/A | M27: Mapping formula : 3 Digits Brand Code + Principal Style Description + SAP (Age/Gender) + SAP Mapping Color Description + Size Description | O27: F | P27: F | Q27: F | R27: F | U27: Principal Style Description | V27: Article Name
A28: SAP Color | B28: =VLOOKUP(A28,MDD!A:B,2,0) -> AT_Color | C28: =VLOOKUP(A28,MDD!A:C,3,0) -> LOV | D28: Basic | E28: Color | F28: MAA 103 Basic SAP Color Code & Description | G28: AI Images Analysist | J28: #N/A | M28: Footwear/Apparel/Accessories Portal Images : Defined from Images by AI (considering LOV) | O28: C | P28: C | Q28: C | R28: C | U28: Principal Merchandise Hierarchy L1 | V28: B2B Product Division
A29: SAP Size | B29: =VLOOKUP(A29,MDD!A:B,2,0) -> AT_Size | C29: =VLOOKUP(A29,MDD!A:C,3,0) -> LOV | D29: Basic | E29: Sizing | F29: MAA SAP Size Code & Description | G29: Mapping from principal | J29: #N/A | M29: Footwear/Apparel/Accessories Principal size will be mapped to SAP size code Notes : The mapping follows LOV For these specific principal size containing "-" in the last character so it should be using H e.g : 10- so 10H, 7- should be 7H. 7.5 should be 7H so on | O29: F | P29: F | Q29: F | R29: F | U29: Principal Merchandise Hierarchy L2 | V29: Product Group
A30: Created on | B30: =VLOOKUP(A30,MDD!A:B,2,0) -> AT_Createdon | C30: =VLOOKUP(A30,MDD!A:C,3,0) -> legacyisodatetime | D30: Basic | F30: When is the creation date | G30: Formula in System | J30: #N/A | M30: Default based on user key in (DD.MM.YYYY) | O30: F | P30: F | Q30: F | R30: F | U30: Principal Merchandise Hierarchy L3 | V30: B2B Business Segment
A31: Created by | B31: =VLOOKUP(A31,MDD!A:B,2,0) -> AT_Createdby | C31: =VLOOKUP(A31,MDD!A:C,3,0) -> text | D31: Basic | F31: Who is creating the articles | G31: Formula in System | J31: #N/A | M31: Default on the creation date (format DD.MM.YYYY) | O31: F | P31: F | Q31: F | R31: F | U31: Principal Merchandise Hierarchy L4 | V31: B2B Product Type
A32: Musical Box Article Code | B32: =VLOOKUP(A32,MDD!A:B,2,0) -> AT_MusicalBoxArticleCode | C32: =VLOOKUP(A32,MDD!A:C,3,0) -> text | D32: Basic | F32: MAA Musical Box Code (Max 18 Digits - 3 Digits brand code + 3 digits of MB- +9 digits of SAP Style Code + 3 Digits Assortment Code) | G32: Not Avaiable | J32: #N/A | M32: N/A | O32: E | P32: E | Q32: E | R32: E | U32: Principal Merchandise Hierarchy L5 | V32: B2B Sports Category
A33: MB Style code | B33: =VLOOKUP(A33,MDD!A:B,2,0) -> AT_MBStyleCode | C33: =VLOOKUP(A33,MDD!A:C,3,0) -> text | D33: Basic | F33: Max 12 digits MB Style (MB- + SAP Style Code ) | G33: Not Avaiable | J33: #N/A | M33: N/A | O33: E | P33: E | Q33: E | R33: E | U33: Principal Color Description | V33: B2B Color1
A34: MB Assortment Code | B34: =VLOOKUP(A34,MDD!A:B,2,0) -> AT_MBAssortmentCode | C34: =VLOOKUP(A34,MDD!A:C,3,0) -> LOV | D34: Basic | F34: 3 Digits Assortment code (based on matrix of qty per sizes) | G34: Not Avaiable | J34: #N/A | M34: N/A | O34: E | P34: E | Q34: E | R34: E | U34: Principal Gender Description | V34: B2B Gender
A35: Musical Box Article Description | B35: =VLOOKUP(A35,MDD!A:B,2,0) -> AT_MusicalBoxArticleDescription | C35: =VLOOKUP(A35,MDD!A:C,3,0) -> text | D35: Basic | E35: Description | F35: MAA Musical Box Description Mapping (Max 40 Digits - 3 Digits brand code + Principal style + (Age/Gender) + Color + (-MB) | G35: Not Avaiable | J35: #N/A | M35: N/A | O35: E | P35: E | Q35: E | R35: E | U35: Principal Age Description | V35: B2B Age Group
A36: Musical Box Components Qty | B36: =VLOOKUP(A36,MDD!A:B,2,0) -> AT_MusicalBoxComponentsQty | C36: =VLOOKUP(A36,MDD!A:C,3,0) -> LOV | D36: Basic | F36: Components qty of Musical Box Articles : Breakdown qty per sizes | G36: Not Avaiable | J36: #N/A | M36: N/A | O36: E | P36: E | Q36: E | R36: E | U36: 1. Current Price | V36: TBC
A37: Musical Box UOM | B37: =VLOOKUP(A37,MDD!A:B,2,0) -> AT_MusicalBoxUOM | C37: =VLOOKUP(A37,MDD!A:C,3,0) -> LOV | D37: Basic | F37: UOM for Musical Box (Default : CAR) | G37: Not Avaiable | J37: #N/A | M37: N/A | O37: E | P37: E | Q37: E | R37: E | U37: 2. Original Price
A38: SAP Age | B38: =VLOOKUP(A38,MDD!A:B,2,0) -> AT_SAPAge | C38: =VLOOKUP(A38,MDD!A:C,3,0) -> LOV | D38: Basic | E38: Age | F38: MAA SAP Age (Co - Dependent with Description) E.g : CH - Children AA - All Ages AD - Adults | G38: Formula in System | J38: #N/A | M38: Footwear/Apparel/Accessories Source: Linelist & DTB (Downloaded from portal) : 'Age Group' Column: Age Group Mapping: Adult = Adult Adults = Adult Infant = Children Infants = Children Junior = Children Youth = Children Children = Children Kids = Children | O38: B | P38: B | Q38: B | R38: B | U38: Principal Sizes | V38: Tab: EAN UPC. Column: Display Size-United Kingdom
A39: SAP Gender | B39: =VLOOKUP(A39,MDD!A:B,2,0) -> AT_Gender | C39: =VLOOKUP(A39,MDD!A:C,3,0) -> LOV | D39: Basic | E39: Gender | F39: MAA SAP Gender (co dependent with description) E.g : M - Male F - Female U - Unisex | G39: Formula in System | J39: #N/A | M39: Footwear/ Apparel/ Accesories Source: Linelist & DTB (downloaded from portal) Column: Gender Mapping: M = Male (M) W = Female (W) U = Unisex (U) Female : Female (W) Women : Female (W) Male : Male (M) Men : Male (M) Unisex : Unisex (U) | O39: B | P39: B | Q39: B | R39: B | U39: Principal Barcode | V39: Tab: EAN UPC. Column: EAN Number
A40: Season | B40: =VLOOKUP(A40,MDD!A:B,2,0) -> AT_Season | C40: =VLOOKUP(A40,MDD!A:C,3,0) -> LOV | D40: Basic | F40: MAA SAP Season (Co Dependent with Description) E.g : SP - Spring SM - Summer FW - Fall Winter SS - Spring Summer etc (refer to LOV) | G40: Manual Input in Portal | J40: TBC | O40: D | P40: D | Q40: D | R40: D | U40: Product Fit | V40: B2B Consumer Fit
...

Sheet Sample Lotto - Inline
A2: Stibo Attribute | B2: Stibo Attribute ID | C2: Stibo Validation | D2: Cluster | E2: Grouping | F2: Attributes Description | G2: Field Mapping Type | H2: Brand File Name & Link | I2: Brand File Sheet Name | J2: Field Name in the Brand File | K2: Mapping Logic | L2: Mapping file for additional Brand specific mapping
A3: Country | B3: =VLOOKUP(A3,MDD!A:B,2,0) -> AT_Country | C3: =VLOOKUP(A3,MDD!A:C,3,0) -> LOV | D3: Basic | F3: Co Dependent with Description E.g : ID - Indonesia PH - Philiphine TH - Thailand SG - Singapore MY - Malaysia VN - Vietnam KH : Cambodia
A4: Company | B4: =VLOOKUP(A4,MDD!A:B,2,0) -> AT_CompanyCode | C4: =VLOOKUP(A4,MDD!A:C,3,0) -> LOV | D4: Basic | F4: Co Dependent with Description 0888 - PT. Map Aktif Adiperkasa 0886 - PT. MAP FTL Adiperkasa 0882 - Magna Management Asia etc (Refer to LOV)
A5: SBU | B5: =VLOOKUP(A5,MDD!A:B,2,0) -> AT_SBU | C5: =VLOOKUP(A5,MDD!A:C,3,0) -> LOV | D5: Basic | F5: Co Dependent with Description E.g SP - Sports FQ - Footlocker Etc (refer to LOV)
A6: Brand | B6: =VLOOKUP(A6,MDD!A:B,2,0) -> AT_Brand | C6: =VLOOKUP(A6,MDD!A:C,3,0) -> LOV | D6: Basic | F6: Co Dependent with Description E.g ADI - Adidas NIK - Nike NEW - New Balance Etc (refer to LOV)
A7: Brand Group | B7: =VLOOKUP(A7,MDD!A:B,2,0) -> AT_BrandGroup | C7: =VLOOKUP(A7,MDD!A:C,3,0) -> LOV | D7: Basic | F7: Multiple brand codes that managed under 1 brand group e.g. Adidas, Lego, Hasbro
A8: Brand Type | B8: =VLOOKUP(A8,MDD!A:B,2,0) -> AT_BrandType | C8: =VLOOKUP(A8,MDD!A:C,3,0) -> LOV | D8: Commercial | F8: Whether a brand act as a retailer, selling directly to customers (MAA brands, SDI brands) or as a distributor (Non-MAA brands, Non-SDI brands)
A9: Brand Category | B9: =VLOOKUP(A9,MDD!A:B,2,0) -> AT_BrandCategory | C9: =VLOOKUP(A9,MDD!A:C,3,0) -> LOV | D9: Commercial | F9: Group of brands that classified based on their performance/ contribution e.g. Top brands, Selected brands, Non-Top brands
A10: Brand Status | B10: =VLOOKUP(A10,MDD!A:B,2,0) -> AT_BrandStatus | C10: =VLOOKUP(A10,MDD!A:C,3,0) -> LOV | D10: Commercial | F10: Indicating whether the brands is actively being sold or, no longer continued or exit the market (Active/Discontinue)
A11: BY Indicator | B11: =VLOOKUP(A11,MDD!A:B,2,0) -> AT_BYIndicator | C11: =VLOOKUP(A11,MDD!A:C,3,0) -> LOV | D11: System indicator | F11: Article to be ordered
A12: SAP Indicator | B12: =VLOOKUP(A12,MDD!A:B,2,0) -> AT_SAPIndicator | C12: =VLOOKUP(A12,MDD!A:C,3,0) -> LOV | D12: System indicator | F12: Article has been created
A13: Ecom Indicator | B13: =VLOOKUP(A13,MDD!A:B,2,0) -> AT_EcomIndicator | C13: =VLOOKUP(A13,MDD!A:C,3,0) -> LOV | D13: System indicator | F13: Article to be Publish at Online Sales Channel
A14: Principal Style Code | B14: =VLOOKUP(A14,MDD!A:B,2,0) -> AT_PrincipalStyleCode | C14: =VLOOKUP(A14,MDD!A:C,3,0) -> text | D14: Basic | F14: Original Principal Code
A15: Principal Style Description | B15: =VLOOKUP(A15,MDD!A:B,2,0) -> AT_PrincipalStyleDescription | C15: =VLOOKUP(A15,MDD!A:C,3,0) -> text | D15: Basic | E15: Description | F15: Original Principal Product Name
A16: Principal Color Code | B16: =VLOOKUP(A16,MDD!A:B,2,0) -> AT_PrincipalColorCode | C16: =VLOOKUP(A16,MDD!A:C,3,0) -> text | D16: Basic | E16: Color | F16: Original Principal Color
A17: Principal Color Description | B17: =VLOOKUP(A17,MDD!A:B,2,0) -> AT_PrincipalColorName | C17: =VLOOKUP(A17,MDD!A:C,3,0) -> text | D17: Basic | E17: Color | F17: Original Principal Color Description
A18: Principal Gender Code | B18: =VLOOKUP(A18,MDD!A:B,2,0) -> AT_PrincipalGenderCode | C18: =VLOOKUP(A18,MDD!A:C,3,0) -> text | D18: Basic | E18: Gender | F18: Original Principal Gender
A19: Principal Gender Description | B19: =VLOOKUP(A19,MDD!A:B,2,0) -> AT_PrincipalGenderDescription | C19: =VLOOKUP(A19,MDD!A:C,3,0) -> text | D19: Basic | E19: Gender | F19: Original Principal Gender Description
A20: Principal Age Code | B20: =VLOOKUP(A20,MDD!A:B,2,0) -> AT_PrincipalAgeCode | C20: =VLOOKUP(A20,MDD!A:C,3,0) -> text | D20: Basic | E20: Age | F20: Original Principal Age
A21: Principal Age Description | B21: =VLOOKUP(A21,MDD!A:B,2,0) -> AT_PrincipalAgeDescription | C21: =VLOOKUP(A21,MDD!A:C,3,0) -> text | D21: Basic | E21: Age | F21: Original Principal Age Description
A22: Principal Size | B22: =VLOOKUP(A22,MDD!A:B,2,0) -> AT_PrincipalSize | C22: =VLOOKUP(A22,MDD!A:C,3,0) -> text | D22: Basic | E22: Sizing | F22: Original Size from Principal (co-dependent with description)
A23: SAP Style Code | B23: =VLOOKUP(A23,MDD!A:B,2,0) -> AT_SAPStyleCode | C23: =VLOOKUP(A23,MDD!A:C,3,0) -> text | D23: Basic | F23: Adjusted principal style code that has been map to SAP generic (without brand code)
A24: Generic | B24: =VLOOKUP(A24,MDD!A:B,2,0) -> AT_Generic | C24: =VLOOKUP(A24,MDD!A:C,3,0) -> text | D24: Basic | F24: MAA Generic Code (Max 12 Digits - 3 Digits brand code + 9 Digits Principal Style)
A25: Generic Description | B25: =VLOOKUP(A25,MDD!A:B,2,0) -> AT_GenericDescription | C25: =VLOOKUP(A25,MDD!A:C,3,0) -> regexp | D25: Basic | E25: Description | F25: MAA Generic Description Mapping (Max 40 Digits - 3 Digits brand code + Principal style + (Age/Gender) + Color
A26: Variant | B26: =VLOOKUP(A26,MDD!A:B,2,0) -> AT_Variant | C26: =VLOOKUP(A26,MDD!A:C,3,0) -> text | D26: Basic | F26: MAA Article Code (Max 18 Digits - Generic code + 3 Digits MAA / SAP Color (103 color guidance) + 3 Digits MAA size code mapping
A27: Variant Description | B27: =VLOOKUP(A27,MDD!A:B,2,0) -> AT_VariantDescription | C27: =VLOOKUP(A27,MDD!A:C,3,0) -> text | D27: Basic | E27: Description | F27: MAA Generic Description Mapping (Max 40 Digits - 3 Digits brand code + Principal style + (Age/Gender) + Color + Size
A28: SAP Color | B28: =VLOOKUP(A28,MDD!A:B,2,0) -> AT_Color | C28: =VLOOKUP(A28,MDD!A:C,3,0) -> LOV | D28: Basic | E28: Color | F28: MAA 103 Basic SAP Color Code & Description
A29: SAP Size | B29: =VLOOKUP(A29,MDD!A:B,2,0) -> AT_Size | C29: =VLOOKUP(A29,MDD!A:C,3,0) -> LOV | D29: Basic | E29: Sizing | F29: MAA SAP Size Code & Description
A30: Created on | B30: =VLOOKUP(A30,MDD!A:B,2,0) -> AT_Createdon | C30: =VLOOKUP(A30,MDD!A:C,3,0) -> legacyisodatetime | D30: Basic | F30: When is the creation date
A31: Created by | B31: =VLOOKUP(A31,MDD!A:B,2,0) -> AT_Createdby | C31: =VLOOKUP(A31,MDD!A:C,3,0) -> text | D31: Basic | F31: Who is creating the articles
A32: Musical Box Article Code | B32: =VLOOKUP(A32,MDD!A:B,2,0) -> AT_MusicalBoxArticleCode | C32: =VLOOKUP(A32,MDD!A:C,3,0) -> text | D32: Basic | F32: MAA Musical Box Code (Max 18 Digits - 3 Digits brand code + 3 digits of MB- +9 digits of SAP Style Code + 3 Digits Assortment Code)
A33: MB Style code | B33: =VLOOKUP(A33,MDD!A:B,2,0) -> AT_MBStyleCode | C33: =VLOOKUP(A33,MDD!A:C,3,0) -> text | D33: Basic | F33: Max 12 digits MB Style (MB- + SAP Style Code )
A34: MB Assortment Code | B34: =VLOOKUP(A34,MDD!A:B,2,0) -> AT_MBAssortmentCode | C34: =VLOOKUP(A34,MDD!A:C,3,0) -> LOV | D34: Basic | F34: 3 Digits Assortment code (based on matrix of qty per sizes)
A35: Musical Box Article Description | B35: =VLOOKUP(A35,MDD!A:B,2,0) -> AT_MusicalBoxArticleDescription | C35: =VLOOKUP(A35,MDD!A:C,3,0) -> text | D35: Basic | E35: Description | F35: MAA Musical Box Description Mapping (Max 40 Digits - 3 Digits brand code + Principal style + (Age/Gender) + Color + (-MB)
A36: Musical Box Components Qty | B36: =VLOOKUP(A36,MDD!A:B,2,0) -> AT_MusicalBoxComponentsQty | C36: =VLOOKUP(A36,MDD!A:C,3,0) -> LOV | D36: Basic | F36: Components qty of Musical Box Articles : Breakdown qty per sizes
A37: Musical Box UOM | B37: =VLOOKUP(A37,MDD!A:B,2,0) -> AT_MusicalBoxUOM | C37: =VLOOKUP(A37,MDD!A:C,3,0) -> LOV | D37: Basic | F37: UOM for Musical Box (Default : CAR)
A38: SAP Age | B38: =VLOOKUP(A38,MDD!A:B,2,0) -> AT_SAPAge | C38: =VLOOKUP(A38,MDD!A:C,3,0) -> LOV | D38: Basic | E38: Age | F38: MAA SAP Age (Co - Dependent with Description) E.g : CH - Children AA - All Ages AD - Adults
A39: SAP Gender | B39: =VLOOKUP(A39,MDD!A:B,2,0) -> AT_Gender | C39: =VLOOKUP(A39,MDD!A:C,3,0) -> LOV | D39: Basic | E39: Gender | F39: MAA SAP Gender (co dependent with description) E.g : M - Male F - Female U - Unisex
A40: Season | B40: =VLOOKUP(A40,MDD!A:B,2,0) -> AT_Season | C40: =VLOOKUP(A40,MDD!A:C,3,0) -> LOV | D40: Basic | F40: MAA SAP Season (Co Dependent with Description) E.g : SP - Spring SM - Summer FW - Fall Winter SS - Spring Summer etc (refer to LOV)
A41: Season Year | B41: =VLOOKUP(A41,MDD!A:B,2,0) -> AT_SeasonYear | C41: =VLOOKUP(A41,MDD!A:C,3,0) -> number | D41: Basic | F41: MAA SAP Year
...

Sheet Sample - 2XU
A2: Stibo Attribute | B2: Stibo Attribute ID | C2: Stibo Validation | D2: Cluster | E2: Grouping | F2: Attributes Description | G2: Field Mapping Type | H2: Brand File Name & Link | I2: Brand File Sheet Name | J2: Field Name in the Brand File | K2: Mapping Logic | L2: Mapping file for additional Brand specific mapping
A3: Country | B3: =VLOOKUP(A3,MDD!A:B,2,0) -> AT_Country | C3: =VLOOKUP(A3,MDD!A:C,3,0) -> LOV | D3: Basic | F3: Co Dependent with Description E.g : ID - Indonesia PH - Philiphine TH - Thailand SG - Singapore MY - Malaysia VN - Vietnam KH : Cambodia | G3: Manual Input | I3: NA | J3: NA
A4: Company | B4: =VLOOKUP(A4,MDD!A:B,2,0) -> AT_CompanyCode | C4: =VLOOKUP(A4,MDD!A:C,3,0) -> LOV | D4: Basic | F4: Co Dependent with Description 0888 - PT. Map Aktif Adiperkasa 0886 - PT. MAP FTL Adiperkasa 0882 - Magna Management Asia etc (Refer to LOV) | G4: Manual Input | I4: NA | J4: NA
A5: SBU | B5: =VLOOKUP(A5,MDD!A:B,2,0) -> AT_SBU | C5: =VLOOKUP(A5,MDD!A:C,3,0) -> LOV | D5: Basic | F5: Co Dependent with Description E.g SP - Sports FQ - Footlocker Etc (refer to LOV) | G5: Manual Input | I5: NA | J5: NA
A6: Brand | B6: =VLOOKUP(A6,MDD!A:B,2,0) -> AT_Brand | C6: =VLOOKUP(A6,MDD!A:C,3,0) -> LOV | D6: Basic | F6: Co Dependent with Description E.g ADI - Adidas NIK - Nike NEW - New Balance Etc (refer to LOV) | G6: Manual Input | I6: NA | J6: NA
A7: Brand Group | B7: =VLOOKUP(A7,MDD!A:B,2,0) -> AT_BrandGroup | C7: =VLOOKUP(A7,MDD!A:C,3,0) -> LOV | D7: Basic | F7: Multiple brand codes that managed under 1 brand group e.g. Adidas, Lego, Hasbro | G7: Formula | I7: NA | J7: NA
A8: Brand Type | B8: =VLOOKUP(A8,MDD!A:B,2,0) -> AT_BrandType | C8: =VLOOKUP(A8,MDD!A:C,3,0) -> LOV | D8: Commercial | F8: Whether a brand act as a retailer, selling directly to customers (MAA brands, SDI brands) or as a distributor (Non-MAA brands, Non-SDI brands) | G8: Formula | I8: NA | J8: NA
A9: Brand Category | B9: =VLOOKUP(A9,MDD!A:B,2,0) -> AT_BrandCategory | C9: =VLOOKUP(A9,MDD!A:C,3,0) -> LOV | D9: Commercial | F9: Group of brands that classified based on their performance/ contribution e.g. Top brands, Selected brands, Non-Top brands | G9: Formula | I9: NA | J9: NA
A10: Brand Status | B10: =VLOOKUP(A10,MDD!A:B,2,0) -> AT_BrandStatus | C10: =VLOOKUP(A10,MDD!A:C,3,0) -> LOV | D10: Commercial | F10: Indicating whether the brands is actively being sold or, no longer continued or exit the market (Active/Discontinue) | G10: Formula | I10: NA | J10: NA
A11: BY Indicator | B11: =VLOOKUP(A11,MDD!A:B,2,0) -> AT_BYIndicator | C11: =VLOOKUP(A11,MDD!A:C,3,0) -> LOV | D11: System indicator | F11: Article to be ordered | G11: Formula | I11: NA | J11: NA
A12: SAP Indicator | B12: =VLOOKUP(A12,MDD!A:B,2,0) -> AT_SAPIndicator | C12: =VLOOKUP(A12,MDD!A:C,3,0) -> LOV | D12: System indicator | F12: Article has been created | G12: Formula | H12: NA | I12: NA | J12: NA
A13: Ecom Indicator | B13: =VLOOKUP(A13,MDD!A:B,2,0) -> AT_EcomIndicator | C13: =VLOOKUP(A13,MDD!A:C,3,0) -> LOV | D13: System indicator | F13: Article to be Publish at Online Sales Channel
A14: Principal Style Code | B14: =VLOOKUP(A14,MDD!A:B,2,0) -> AT_PrincipalStyleCode | C14: =VLOOKUP(A14,MDD!A:C,3,0) -> text | D14: Basic | F14: Original Principal Code | G14: Mapping from Principal | H14: H1 27 Product Bible.xlsx | J14: Product Code
A15: Principal Style Description | B15: =VLOOKUP(A15,MDD!A:B,2,0) -> AT_PrincipalStyleDescription | C15: =VLOOKUP(A15,MDD!A:C,3,0) -> text | D15: Basic | E15: Description | F15: Original Principal Product Name | G15: Mapping from Principal | H15: H1 27 Product Bible.xlsx | J15: Product Name
A16: Principal Color Code | B16: =VLOOKUP(A16,MDD!A:B,2,0) -> AT_PrincipalColorCode | C16: =VLOOKUP(A16,MDD!A:C,3,0) -> text | D16: Basic | E16: Color | F16: Original Principal Color | G16: Mapping from Principal | H16: H1 27 Product Bible.xlsx | J16: Colour Code
A17: Principal Color Description | B17: =VLOOKUP(A17,MDD!A:B,2,0) -> AT_PrincipalColorName | C17: =VLOOKUP(A17,MDD!A:C,3,0) -> text | D17: Basic | E17: Color | F17: Original Principal Color Description | G17: Mapping from Principal | H17: H1 27 Product Bible.xlsx | J17: Colour Description
A18: Principal Gender Code | B18: =VLOOKUP(A18,MDD!A:B,2,0) -> AT_PrincipalGenderCode | C18: =VLOOKUP(A18,MDD!A:C,3,0) -> text | D18: Basic | E18: Gender | F18: Original Principal Gender
A19: Principal Gender Description | B19: =VLOOKUP(A19,MDD!A:B,2,0) -> AT_PrincipalGenderDescription | C19: =VLOOKUP(A19,MDD!A:C,3,0) -> text | D19: Basic | E19: Gender | F19: Original Principal Gender Description | G19: Mapping from Principal | H19: H1 27 Product Bible.xlsx | J19: Gender
A20: Principal Age Code | B20: =VLOOKUP(A20,MDD!A:B,2,0) -> AT_PrincipalAgeCode | C20: =VLOOKUP(A20,MDD!A:C,3,0) -> text | D20: Basic | E20: Age | F20: Original Principal Age
A21: Principal Age Description | B21: =VLOOKUP(A21,MDD!A:B,2,0) -> AT_PrincipalAgeDescription | C21: =VLOOKUP(A21,MDD!A:C,3,0) -> text | D21: Basic | E21: Age | F21: Original Principal Age Description
A22: Principal Size | B22: =VLOOKUP(A22,MDD!A:B,2,0) -> AT_PrincipalSize | C22: =VLOOKUP(A22,MDD!A:C,3,0) -> text | D22: Basic | E22: Sizing | F22: Original Size from Principal (co-dependent with description) | G22: Mapping from Principal | H22: H1 27 Product Bible.xlsx | I22: EAN Barcode | J22: Size
A23: SAP Style Code | B23: =VLOOKUP(A23,MDD!A:B,2,0) -> AT_SAPStyleCode | C23: =VLOOKUP(A23,MDD!A:C,3,0) -> text | D23: Basic | F23: Adjusted principal style code that has been map to SAP generic (without brand code) | G23: Formula | K23: "Apparel & Accessories Max 9 Digits : 7 Digits Principal Style Code + 2 Digits MD Mapping Example : UQ7707E WHT/BLK Result : UQ7707EWB" | L23: 2XU - Stibo Mapping (upd. 21 April 2026).xlsx
A24: Generic | B24: =VLOOKUP(A24,MDD!A:B,2,0) -> AT_Generic | C24: =VLOOKUP(A24,MDD!A:C,3,0) -> text | D24: Basic | F24: MAA Generic Code (Max 12 Digits - 3 Digits brand code + 9 Digits Principal Style)
A25: Generic Description | B25: =VLOOKUP(A25,MDD!A:B,2,0) -> AT_GenericDescription | C25: =VLOOKUP(A25,MDD!A:C,3,0) -> regexp | D25: Basic | E25: Description | F25: MAA Generic Description Mapping (Max 40 Digits - 3 Digits brand code + Principal style + (Age/Gender) + Color
A26: Variant | B26: =VLOOKUP(A26,MDD!A:B,2,0) -> AT_Variant | C26: =VLOOKUP(A26,MDD!A:C,3,0) -> text | D26: Basic | F26: MAA Article Code (Max 18 Digits - Generic code + 3 Digits MAA / SAP Color (103 color guidance) + 3 Digits MAA size code mapping
A27: Variant Description | B27: =VLOOKUP(A27,MDD!A:B,2,0) -> AT_VariantDescription | C27: =VLOOKUP(A27,MDD!A:C,3,0) -> text | D27: Basic | E27: Description | F27: MAA Generic Description Mapping (Max 40 Digits - 3 Digits brand code + Principal style + (Age/Gender) + Color + Size
A28: SAP Color | B28: =VLOOKUP(A28,MDD!A:B,2,0) -> AT_Color | C28: =VLOOKUP(A28,MDD!A:C,3,0) -> LOV | D28: Basic | E28: Color | F28: MAA 103 Basic SAP Color Code & Description
A29: SAP Size | B29: =VLOOKUP(A29,MDD!A:B,2,0) -> AT_Size | C29: =VLOOKUP(A29,MDD!A:C,3,0) -> LOV | D29: Basic | E29: Sizing | F29: MAA SAP Size Code & Description
A30: Created on | B30: =VLOOKUP(A30,MDD!A:B,2,0) -> AT_Createdon | C30: =VLOOKUP(A30,MDD!A:C,3,0) -> legacyisodatetime | D30: Basic | F30: When is the creation date
A31: Created by | B31: =VLOOKUP(A31,MDD!A:B,2,0) -> AT_Createdby | C31: =VLOOKUP(A31,MDD!A:C,3,0) -> text | D31: Basic | F31: Who is creating the articles
A32: Musical Box Article Code | B32: =VLOOKUP(A32,MDD!A:B,2,0) -> AT_MusicalBoxArticleCode | C32: =VLOOKUP(A32,MDD!A:C,3,0) -> text | D32: Basic | F32: MAA Musical Box Code (Max 18 Digits - 3 Digits brand code + 3 digits of MB- +9 digits of SAP Style Code + 3 Digits Assortment Code)
A33: MB Style code | B33: =VLOOKUP(A33,MDD!A:B,2,0) -> AT_MBStyleCode | C33: =VLOOKUP(A33,MDD!A:C,3,0) -> text | D33: Basic | F33: Max 12 digits MB Style (MB- + SAP Style Code )
A34: MB Assortment Code | B34: =VLOOKUP(A34,MDD!A:B,2,0) -> AT_MBAssortmentCode | C34: =VLOOKUP(A34,MDD!A:C,3,0) -> LOV | D34: Basic | F34: 3 Digits Assortment code (based on matrix of qty per sizes)
A35: Musical Box Article Description | B35: =VLOOKUP(A35,MDD!A:B,2,0) -> AT_MusicalBoxArticleDescription | C35: =VLOOKUP(A35,MDD!A:C,3,0) -> text | D35: Basic | E35: Description | F35: MAA Musical Box Description Mapping (Max 40 Digits - 3 Digits brand code + Principal style + (Age/Gender) + Color + (-MB)
A36: Musical Box Components Qty | B36: =VLOOKUP(A36,MDD!A:B,2,0) -> AT_MusicalBoxComponentsQty | C36: =VLOOKUP(A36,MDD!A:C,3,0) -> LOV | D36: Basic | F36: Components qty of Musical Box Articles : Breakdown qty per sizes
A37: Musical Box UOM | B37: =VLOOKUP(A37,MDD!A:B,2,0) -> AT_MusicalBoxUOM | C37: =VLOOKUP(A37,MDD!A:C,3,0) -> LOV | D37: Basic | F37: UOM for Musical Box (Default : CAR)
A38: SAP Age | B38: =VLOOKUP(A38,MDD!A:B,2,0) -> AT_SAPAge | C38: =VLOOKUP(A38,MDD!A:C,3,0) -> LOV | D38: Basic | E38: Age | F38: MAA SAP Age (Co - Dependent with Description) E.g : CH - Children AA - All Ages AD - Adults
A39: SAP Gender | B39: =VLOOKUP(A39,MDD!A:B,2,0) -> AT_Gender | C39: =VLOOKUP(A39,MDD!A:C,3,0) -> LOV | D39: Basic | E39: Gender | F39: MAA SAP Gender (co dependent with description) E.g : M - Male F - Female U - Unisex
A40: Season | B40: =VLOOKUP(A40,MDD!A:B,2,0) -> AT_Season | C40: =VLOOKUP(A40,MDD!A:C,3,0) -> LOV | D40: Basic | F40: MAA SAP Season (Co Dependent with Description) E.g : SP - Spring SM - Summer FW - Fall Winter SS - Spring Summer etc (refer to LOV)
A41: Season Year | B41: =VLOOKUP(A41,MDD!A:B,2,0) -> AT_SeasonYear | C41: =VLOOKUP(A41,MDD!A:C,3,0) -> number | D41: Basic | F41: MAA SAP Year
...

Sheet Crocs(Inline)
A2: Stibo Attribute | B2: Stibo Attribute ID | C2: Stibo Validation | D2: Cluster | E2: Grouping | F2: Attributes Description | G2: Field Mapping Type | H2: Brand File Name & Link | I2: Brand File Sheet Name | J2: Field Name in the Brand File | K2: Mapping Logic | L2: Mapping file for additional Brand specific mapping
A3: Country | B3: =VLOOKUP(A3,MDD!A:B,2,0) -> AT_Country | C3: LOV | F3: "Co Dependent with Description E.g : ID - Indonesia PH - Philiphine TH - Thailand SG - Singapore MY - Malaysia VN - Vietnam KH : Cambodia" | G3: Manual Input
A4: Company | B4: =VLOOKUP(A4,MDD!A:B,2,0) -> AT_CompanyCode | C4: LOV | F4: "Co Dependent with Description 0888 - PT. Map Aktif Adiperkasa 0886 - PT. MAP FTL Adiperkasa 0882 - Magna Management Asia etc (Refer to LOV)" | G4: Manual Input
A5: SBU | B5: =VLOOKUP(A5,MDD!A:B,2,0) -> AT_SBU | C5: LOV | F5: "Co Dependent with Description E.g SP - Sports FQ - Footlocker Etc (refer to LOV)" | G5: Manual Input
A6: Brand | B6: =VLOOKUP(A6,MDD!A:B,2,0) -> AT_Brand | C6: LOV | F6: "Co Dependent with Description E.g ADI - Adidas NIK - Nike NEW - New Balance Etc (refer to LOV)" | G6: Manual Input
A7: Brand Group | B7: =VLOOKUP(A7,MDD!A:B,2,0) -> AT_BrandGroup | C7: LOV | F7: Multiple brand codes that managed under 1 brand group e.g. Adidas, Lego, Hasbro | G7: Formula in system
A8: Brand Type | B8: =VLOOKUP(A8,MDD!A:B,2,0) -> AT_BrandType | C8: LOV | F8: Whether a brand act as a retailer, selling directly to customers (MAA brands, SDI brands) or as a distributor (Non-MAA brands, Non-SDI brands) | G8: Formula in system
A9: Brand Category | B9: =VLOOKUP(A9,MDD!A:B,2,0) -> AT_BrandCategory | C9: LOV | F9: Group of brands that classified based on their performance/ contribution e.g. Top brands, Selected brands, Non-Top brands | G9: Formula in system
A10: Brand Status | B10: =VLOOKUP(A10,MDD!A:B,2,0) -> AT_BrandStatus | C10: =VLOOKUP(A10,MDD!A:C,3,0) -> LOV | F10: Indicating whether the brands is actively being sold or, no longer continued or exit the market (Active/Discontinue) | G10: Formula in system
A11: BY Indicator | B11: =VLOOKUP(A11,MDD!A:B,2,0) -> AT_BYIndicator | C11: =VLOOKUP(A11,MDD!A:C,3,0) -> LOV | F11: Article to be ordered | G11: Formula in system
A12: SAP Indicator | B12: =VLOOKUP(A12,MDD!A:B,2,0) -> AT_SAPIndicator | C12: =VLOOKUP(A12,MDD!A:C,3,0) -> LOV | F12: Article has been created | G12: Formula in system
A13: Ecom Indicator | B13: =VLOOKUP(A13,MDD!A:B,2,0) -> AT_EcomIndicator | C13: =VLOOKUP(A13,MDD!A:C,3,0) -> LOV | F13: Article to be Publish at Online Sales Channel | G13: Manual Input
A14: Principal Style Code | B14: =VLOOKUP(A14,MDD!A:B,2,0) -> AT_PrincipalStyleCode | C14: Text | F14: Original Principal Code | G14: Direct from Principal | H14: S1 26 SEA Line List (SEA) (2).xlsb | J14: Colorway Code | K14: "FW & Acc Line List : Column 'Colorway Code'"
A15: Principal Style Description | B15: =VLOOKUP(A15,MDD!A:B,2,0) -> AT_PrincipalStyleDescription | C15: Text | E15: Description | F15: Original Principal Product Name | G15: Direct from Principal | H15: S1 26 SEA Line List (SEA) (2).xlsb | J15: Style | K15: "FW & Acc Line List : Column 'Style' "
A16: Principal Color Code | B16: =VLOOKUP(A16,MDD!A:B,2,0) -> AT_PrincipalColorCode | C16: Text | E16: Color | F16: Original Principal Color | G16: Formula in system | H16: S1 26 SEA Line List (SEA) (2).xlsb | J16: Colorway Code | K16: "FW & Acc Line List : Column 'Colorway Code' (put the last 3 digits)"
A17: Principal Color Description | B17: =VLOOKUP(A17,MDD!A:B,2,0) -> AT_PrincipalColorName | C17: Text | E17: Color | F17: Original Principal Color Description | G17: Direct from Principal | H17: S1 26 SEA Line List (SEA) (2).xlsb | J17: Colorway | K17: "FW & Acc Line List : Column 'Colorway'"
A18: Principal Gender Code | B18: =VLOOKUP(A18,MDD!A:B,2,0) -> AT_PrincipalGenderCode | E18: Gender | F18: Original Principal Gender | G18: N/A
A19: Principal Gender Description | B19: =VLOOKUP(A19,MDD!A:B,2,0) -> AT_PrincipalGenderDescription | E19: Gender | F19: Original Principal Gender Description | G19: Direct from Principal | H19: S1 26 SEA Line List (SEA) (2).xlsb | J19: Gender | K19: "FW & Acc Line list : Column 'Gender'"
A20: Principal Age Code | B20: =VLOOKUP(A20,MDD!A:B,2,0) -> AT_PrincipalAgeCode | E20: Age | F20: Original Principal Age | G20: N/A
A21: Principal Age Description | B21: =VLOOKUP(A21,MDD!A:B,2,0) -> AT_PrincipalAgeDescription | E21: Age | F21: Original Principal Age Description | G21: N/A
A22: Principal Size Code | B22: AT_PrincipalStyleCode | E22: Sizing | F22: Original Size from Principal (co-dependent with description) | G22: Direct from Principal | H22: S1 26 SEA Line List (SEA) (2).xlsb | J22: Size Range (Colorway) | K22: FW & Acc_x000D_ Line list : Column 'Size Range' (Colorway)
A23: SAP Style Code | B23: =VLOOKUP(A23,MDD!A:B,2,0) -> AT_SAPStyleCode | F23: Adjusted principal style code that has been map to SAP generic (without brand code) | G23: Mapping from Principal | H23: S1 26 SEA Line List (SEA) (2).xlsb | J23: Colorway Code | K23: "FW & Acc Line List : Column 'Colorway Code' FW : (if more than 9, delete ""-"") ex: 212953-90H -> 21295390H JBZ : (add ""-"" after 3 digits) EX:10016475 -> 100-16475"
A24: Generic | B24: =VLOOKUP(A24,MDD!A:B,2,0) -> AT_Generic | F24: MAA Generic Code (Max 12 Digits - 3 Digits brand code + 9 Digits Principal Style) | G24: Mapping from Principal | H24: S1 26 SEA Line List (SEA) (2).xlsb | J24: Colorway Code | K24: "FW & Acc Line List : Column 'Colorway Code' Mapping with rules FW : (if more than 12, delete ""-"") ex: 212953-90H -> CCR21295390H JBZ : (add ""-"" after 3 digits) EX:10016475 -> CCR100-16475"
A25: Generic Description | B25: =VLOOKUP(A25,MDD!A:B,2,0) -> AT_GenericDescription | E25: Description | F25: MAA Generic Description Mapping (Max 40 Digits - 3 Digits brand code + Principal style + (Age/Gender) + Color | G25: Mapping from Principal | K25: MAA Generic Description Mapping (Max 40 Digits - 3 Digits brand code + Principal style + (Age/Gender) + Color
A26: Variant | B26: =VLOOKUP(A26,MDD!A:B,2,0) -> AT_Variant | F26: MAA Article Code (Max 18 Digits - Generic code + 3 Digits MAA / SAP Color (103 color guidance) + 3 Digits MAA size code mapping | G26: Mapping from Principal | K26: "FW & Acc 3 Digits Brand Code + Max 9 DIgits Principal Style Code + 3 digits SAP Color code + 3 digits Size code"
A27: Variant Description | B27: =VLOOKUP(A27,MDD!A:B,2,0) -> AT_VariantDescription | E27: Description | F27: MAA Generic Description Mapping (Max 40 Digits - 3 Digits brand code + Principal style + (Age/Gender) + Color + Size | G27: Mapping from Principal | K27: "FW & Acc MAA Generic Description Mapping (Max 40 Digits - 3 Digits brand code + Principal style + (Age/Gender) + Color + Size Shorten: Classic -Cls/Cs, Clog - Clg/Cg Platform - Pltfrm, Sandal-Sndl (have no fix mapping for shorten the desc) Jibbitz - Jbz, 5 Pack-5P/5Pck"
A28: SAP Color | B28: =VLOOKUP(A28,MDD!A:B,2,0) -> AT_Color | E28: Color | F28: MAA 103 Basic SAP Color Code & Description | G28: Defined from Images | K28: "FW :Defined from Images by AI Acc : Define by AI Default 'No color' Acc - Bag : Defined from Images by AI "
A29: SAP Size | B29: =VLOOKUP(A29,MDD!A:B,2,0) -> AT_Size | E29: Sizing | F29: MAA SAP Size Code & Description | G29: Mapping from Principal | J29: Size Range | K29: "FW : Line list : Size Range (refer to LOV) Acc Bags : Default 'No Size'"
A30: Created on | B30: =VLOOKUP(A30,MDD!A:B,2,0) -> AT_Createdon | C30: =VLOOKUP(A30,MDD!A:C,3,0) -> legacyisodatetime | D30: Basic | F30: When is the creation date | G30: Formula in system
A31: Created by | B31: =VLOOKUP(A31,MDD!A:B,2,0) -> AT_Createdby | C31: =VLOOKUP(A31,MDD!A:C,3,0) -> text | D31: Basic | F31: Who is creating the articles | G31: Formula in system
A32: Musical Box Article Code | B32: =VLOOKUP(A32,MDD!A:B,2,0) -> AT_MusicalBoxArticleCode | C32: =VLOOKUP(A32,MDD!A:C,3,0) -> text | F32: MAA Musical Box Code (Max 18 Digits - 3 Digits brand code + 3 digits of MB- +9 digits of SAP Style Code + 3 Digits Assortment Code)
A33: MB Style code | B33: =VLOOKUP(A33,MDD!A:B,2,0) -> AT_MBStyleCode | C33: =VLOOKUP(A33,MDD!A:C,3,0) -> text | F33: Max 12 digits MB Style (MB- + SAP Style Code )
A34: MB Assortment Code | B34: =VLOOKUP(A34,MDD!A:B,2,0) -> AT_MBAssortmentCode | C34: =VLOOKUP(A34,MDD!A:C,3,0) -> LOV | F34: 3 Digits Assortment code (based on matrix of qty per sizes)
A35: Musical Box Article Description | B35: =VLOOKUP(A35,MDD!A:B,2,0) -> AT_MusicalBoxArticleDescription | C35: =VLOOKUP(A35,MDD!A:C,3,0) -> text | F35: MAA Musical Box Description Mapping (Max 40 Digits - 3 Digits brand code + Principal style + (Age/Gender) + Color + (-MB)
A36: Musical Box Components Qty | B36: =VLOOKUP(A36,MDD!A:B,2,0) -> AT_MusicalBoxComponentsQty | C36: =VLOOKUP(A36,MDD!A:C,3,0) -> LOV | F36: Components qty of Musical Box Articles : Breakdown qty per sizes
A37: Musical Box UOM | B37: =VLOOKUP(A37,MDD!A:B,2,0) -> AT_MusicalBoxUOM | C37: =VLOOKUP(A37,MDD!A:C,3,0) -> LOV | F37: UOM for Musical Box (Default : CAR) | G37: Formula in system | K37: default 'CAR'
A38: SAP Age | B38: =VLOOKUP(A38,MDD!A:B,2,0) -> AT_SAPAge | C38: =VLOOKUP(A38,MDD!A:C,3,0) -> LOV | E38: Age | F38: "MAA SAP Age (Co - Dependent with Description) E.g : CH - Children AA - All Ages AD - Adults" | G38: Mapping from Principal | H38: S1 26 SEA Line List (SEA) (2).xlsb | J38: Gender | K38: "FW Line list : Column 'Gender' (Mapping) Men : Adults Women : Adults Unisex Adults : Adults Unisex Kids : Children Acc : Default 'Adults'"
A39: SAP Gender | B39: =VLOOKUP(A39,MDD!A:B,2,0) -> AT_Gender | C39: =VLOOKUP(A39,MDD!A:C,3,0) -> LOV | E39: Gender | F39: "MAA SAP Gender (co dependent with description) E.g : M - Male F - Female U - Unisex" | G39: Mapping from Principal | H39: S1 26 SEA Line List (SEA) (2).xlsb | J39: Gender | K39: "FW Line list : Column 'Gender' (Mapping) Men : Male Women : Female Unisex Adults : Unisex Unisex Kids : Unisex Acc : Default 'Unisex"
A40: Season | B40: =VLOOKUP(A40,MDD!A:B,2,0) -> AT_Season | C40: =VLOOKUP(A40,MDD!A:C,3,0) -> LOV | F40: "MAA SAP Season (Co Dependent with Description) E.g : SP - Spring SM - Summer FW - Fall Winter SS - Spring Summer etc (refer to LOV) | G40: Manual Input
A41: Season Year | B41: =VLOOKUP(A41,MDD!A:B,2,0) -> AT_SeasonYear | C41: =VLOOKUP(A41,MDD!A:C,3,0) -> number | F41: MAA SAP Year | G41: Manual Input
...

Sheet Crocs(Inline)-NEW
A2: Stibo Attribute | B2: Stibo Attribute ID | C2: Stibo Validation | D2: Cluster | E2: Grouping | F2: Attributes Description | G2: Field Mapping Type | H2: Brand File Name & Link | I2: Brand File Sheet Name | J2: Field Name in the Brand File | K2: Mapping Logic | L2: Mapping file for additional Brand specific mapping
A3: Country | B3: =VLOOKUP(A3,MDD!A:B,2,0) -> AT_Country | C3: LOV | F3: "Co Dependent with Description E.g : ID - Indonesia PH - Philiphine TH - Thailand SG - Singapore MY - Malaysia VN - Vietnam KH : Cambodia" | G3: Manual Input
A4: Company | B4: =VLOOKUP(A4,MDD!A:B,2,0) -> AT_CompanyCode | C4: LOV | F4: "Co Dependent with Description 0888 - PT. Map Aktif Adiperkasa 0886 - PT. MAP FTL Adiperkasa 0882 - Magna Management Asia etc (Refer to LOV)" | G4: Manual Input
A5: SBU | B5: =VLOOKUP(A5,MDD!A:B,2,0) -> AT_SBU | C5: LOV | F5: "Co Dependent with Description E.g SP - Sports FQ - Footlocker Etc (refer to LOV)" | G5: Manual Input
A6: Brand | B6: =VLOOKUP(A6,MDD!A:B,2,0) -> AT_Brand | C6: LOV | F6: "Co Dependent with Description E.g ADI - Adidas NIK - Nike NEW - New Balance Etc (refer to LOV)" | G6: Manual Input
A7: Brand Group | B7: =VLOOKUP(A7,MDD!A:B,2,0) -> AT_BrandGroup | C7: LOV | F7: Multiple brand codes that managed under 1 brand group e.g. Adidas, Lego, Hasbro | G7: Formula in system
A8: Brand Type | B8: =VLOOKUP(A8,MDD!A:B,2,0) -> AT_BrandType | C8: LOV | F8: Whether a brand act as a retailer, selling directly to customers (MAA brands, SDI brands) or as a distributor (Non-MAA brands, Non-SDI brands) | G8: Formula in system
A9: Brand Category | B9: =VLOOKUP(A9,MDD!A:B,2,0) -> AT_BrandCategory | C9: LOV | F9: Group of brands that classified based on their performance/ contribution e.g. Top brands, Selected brands, Non-Top brands | G9: Formula in system
A10: Brand Status | B10: =VLOOKUP(A10,MDD!A:B,2,0) -> AT_BrandStatus | C10: =VLOOKUP(A10,MDD!A:C,3,0) -> LOV | F10: Indicating whether the brands is actively being sold or, no longer continued or exit the market (Active/Discontinue) | G10: Formula in system
A11: BY Indicator | B11: =VLOOKUP(A11,MDD!A:B,2,0) -> AT_BYIndicator | C11: =VLOOKUP(A11,MDD!A:C,3,0) -> LOV | F11: Article to be ordered | G11: Formula in system
A12: SAP Indicator | B12: =VLOOKUP(A12,MDD!A:B,2,0) -> AT_SAPIndicator | C12: =VLOOKUP(A12,MDD!A:C,3,0) -> LOV | F12: Article has been created | G12: Formula in system
A13: Ecom Indicator | B13: =VLOOKUP(A13,MDD!A:B,2,0) -> AT_EcomIndicator | C13: =VLOOKUP(A13,MDD!A:C,3,0) -> LOV | F13: Article to be Publish at Online Sales Channel | G13: Manual Input
A14: Principal Style Code | B14: =VLOOKUP(A14,MDD!A:B,2,0) -> AT_PrincipalStyleCode | C14: Text | F14: Original Principal Code | G14: Direct from Principal | H14: H1 27 SEA Line List - SEA (5.15).xlsx | I14: all sheet should be loaded FTW : Footwear Charms : Accessories (jibbitz) ACC | J14: FW & ACC : Colorway Code Charms : Style Code | K14: FW & ACC : Colorway Code Charms : Style Code
A15: Principal Style Description | B15: =VLOOKUP(A15,MDD!A:B,2,0) -> AT_PrincipalStyleDescription | C15: Text | E15: Description | F15: Original Principal Product Name | G15: Direct from Principal | H15: H1 27 SEA Line List - SEA (5.15).xlsx | I15: all sheet should be loaded FTW : Footwear Charms : Accessories (jibbitz) ACC | J15: Style | K15: "FW & Acc Line List : Column 'Style' "
A16: Principal Color Code | B16: =VLOOKUP(A16,MDD!A:B,2,0) -> AT_PrincipalColorCode | C16: Text | E16: Color | F16: Original Principal Color | G16: Formula in system | H16: H1 27 SEA Line List - SEA (5.15).xlsx | I16: all sheet should be loaded FTW : Footwear Charms : Accessories (jibbitz) ACC | J16: FW & Acc : Colorway Code Charms : N/A | K16: "FW & Acc Line List : Column 'Colorway Code' (put the last 3 digits)" Charms :N/A
A17: Principal Color Description | B17: =VLOOKUP(A17,MDD!A:B,2,0) -> AT_PrincipalColorName | C17: Text | E17: Color | F17: Original Principal Color Description | G17: Direct from Principal | H17: H1 27 SEA Line List - SEA (5.15).xlsx | I17: all sheet should be loaded FTW : Footwear Charms : Accessories (jibbitz) ACC | J17: FW & Acc : Colorway Charms: N/A | K17: FW & Acc : Colorway Charms: N/A
A18: Principal Gender Code | B18: =VLOOKUP(A18,MDD!A:B,2,0) -> AT_PrincipalGenderCode | E18: Gender | F18: Original Principal Gender | G18: N/A | I18: all sheet should be loaded FTW : Footwear Charms : Accessories (jibbitz) ACC
A19: Principal Gender Description | B19: =VLOOKUP(A19,MDD!A:B,2,0) -> AT_PrincipalGenderDescription | E19: Gender | F19: Original Principal Gender Description | G19: Direct from Principal | H19: H1 27 SEA Line List - SEA (5.15).xlsx | I19: all sheet should be loaded FTW : Footwear Charms : Accessories (jibbitz) ACC | J19: FW & Acc : Gender Charms : N/A | K19: FW & Acc : Gender Charms : N/A
A20: Principal Age Code | B20: =VLOOKUP(A20,MDD!A:B,2,0) -> AT_PrincipalAgeCode | E20: Age | F20: Original Principal Age | G20: N/A | I20: all sheet should be loaded FTW : Footwear Charms : Accessories (jibbitz) ACC
A21: Principal Age Description | B21: =VLOOKUP(A21,MDD!A:B,2,0) -> AT_PrincipalAgeDescription | E21: Age | F21: Original Principal Age Description | G21: N/A | I21: all sheet should be loaded FTW : Footwear Charms : Accessories (jibbitz) ACC
A22: Principal Size Code | B22: AT_PrincipalStyleCode | E22: Sizing | F22: Original Size from Principal (co-dependent with description) | G22: Direct from Principal | H22: H1 27 SEA Line List - SEA (5.15).xlsx | I22: all sheet should be loaded FTW : Footwear Charms : Accessories (jibbitz) ACC | J22: Size Range (Colorway) | K22: FW & Acc_x000D_ Line list : Column 'Size Range' (Colorway)
